<sdf version='1.7'>
  <model name='carre_sim'>
    <link name='robot_footprint'>
      <inertial>
        <pose>0.001722 0 0 0 -0 0</pose>
        <mass>15.1</mass>
        <inertia>
          <ixx>0.147118</ixx>
          <ixy>0</ixy>
          <ixz>0</ixz>
          <iyy>0.341667</iyy>
          <iyz>0</iyz>
          <izz>0.404551</izz>
        </inertia>
      </inertial>
      <collision name='robot_footprint_fixed_joint_lump__collision_collision'>
        <pose>0 0 0.05 0 -0 0</pose>
        <geometry>
          <box>
            <size>0.5 0.5 0.2</size>
          </box>
        </geometry>
      </collision>
      <collision name='robot_footprint_fixed_joint_lump__camera_collision_1'>
        <pose>0.26 0 0 0 -0 0</pose>
        <geometry>
          <box>
            <size>0.05 0.05 0.05</size>
          </box>
        </geometry>
        <surface>
          <contact>
            <ode/>
          </contact>
          <friction>
            <ode/>
          </friction>
        </surface>
      </collision>
      <visual name='robot_footprint_fixed_joint_lump__chassis_visual_visual'>
        <pose>0 0 0.05 0 -0 0</pose>
        <geometry>
          <box>
            <size>0.5 0.5 0.2</size>
          </box>
        </geometry>
        <material>
          <script>
            <name>Gazebo/Blue</name>
            <uri>file://media/materials/scripts/gazebo.material</uri>
          </script>
        </material>
      </visual>
      <visual name='robot_footprint_fixed_joint_lump__camera_visual_1'>
        <pose>0.26 0 0 0 -0 0</pose>
        <geometry>
          <box>
            <size>0.05 0.05 0.05</size>
          </box>
        </geometry>
        <material>
          <script>
            <name>Gazebo/Red</name>
            <uri>file://media/materials/scripts/gazebo.material</uri>
          </script>
        </material>
      </visual>
      <sensor name='camera1' type='camera'>
        <update_rate>30</update_rate>
        <camera name='head'>
          <horizontal_fov>2.0944</horizontal_fov>
          <image>
            <width>1920</width>
            <height>1080</height>
            <format>R8G8B8</format>
          </image>
          <clip>
            <near>0.02</near>
            <far>300</far>
          </clip>
        </camera>
        <plugin name='camera_controller' filename='libgazebo_ros_camera.so'>
          <robotNamespace>/carre_sim</robotNamespace>
          <alwaysOn>1</alwaysOn>
          <updateRate>0.0</updateRate>
          <cameraName>camera</cameraName>
          <imageTopicName>rgb/image_raw</imageTopicName>
          <cameraInfoTopicName>rgb/camera_info</cameraInfoTopicName>
          <frameName>camera</frameName>
          <hackBaseline>0.07</hackBaseline>
          <distortionK1>0.0</distortionK1>
          <distortionK2>0.0</distortionK2>
          <distortionK3>0.0</distortionK3>
          <distortionT1>0.0</distortionT1>
          <distortionT2>0.0</distortionT2>
        </plugin>
        <pose>0.26 0 0 0 -0 0</pose>
      </sensor>
    </link>
    <joint name='left_wheel_hinge_back' type='revolute'>
      <pose relative_to='robot_footprint'>-0.2 0.3 0 0 -0 0</pose>
      <parent>robot_footprint</parent>
      <child>left_wheel_back</child>
      <axis>
        <xyz>0 1 0</xyz>
        <limit>
          <effort>10000</effort>
          <velocity>1000</velocity>
          <lower>-1e+16</lower>
          <upper>1e+16</upper>
        </limit>
        <dynamics>
          <damping>1</damping>
          <friction>1</friction>
          <spring_reference>0</spring_reference>
          <spring_stiffness>0</spring_stiffness>
        </dynamics>
      </axis>
    </joint>
    <link name='left_wheel_back'>
      <pose relative_to='left_wheel_hinge_back'>0 0 0 0 -0 0</pose>
      <inertial>
        <pose>0 0 0 0 1.5707 1.5707</pose>
        <mass>5</mass>
        <inertia>
          <ixx>0.1</ixx>
          <ixy>0</ixy>
          <ixz>0</ixz>
          <iyy>0.1</iyy>
          <iyz>0</iyz>
          <izz>0.1</izz>
        </inertia>
      </inertial>
      <collision name='left_wheel_back_collision'>
        <pose>0 0 0 -1.5707 1.5708 0</pose>
        <geometry>
          <cylinder>
            <length>0.05</length>
            <radius>0.1</radius>
          </cylinder>
        </geometry>
        <surface>
          <contact>
            <ode>
              <kp>1e+06</kp>
              <kd>100</kd>
              <max_vel>1</max_vel>
              <min_depth>0</min_depth>
            </ode>
          </contact>
          <friction>
            <ode>
              <mu>1</mu>
              <mu2>1</mu2>
            </ode>
          </friction>
        </surface>
      </collision>
      <visual name='left_wheel_back_visual'>
        <pose>0 0 0 -1.5707 1.5708 0</pose>
        <geometry>
          <cylinder>
            <length>0.05</length>
            <radius>0.1</radius>
          </cylinder>
        </geometry>
        <material>
          <script>
            <name>Gazebo/Green</name>
            <uri>file://media/materials/scripts/gazebo.material</uri>
          </script>
        </material>
      </visual>
    </link>
    <joint name='left_wheel_hinge_front' type='revolute'>
      <pose relative_to='robot_footprint'>0.2 0.3 -0.1 0 -0 0</pose>
      <parent>robot_footprint</parent>
      <child>left_wheel_front</child>
      <axis>
        <xyz>0 1 0</xyz>
        <limit>
          <effort>10000</effort>
          <velocity>1000</velocity>
          <lower>-1e+16</lower>
          <upper>1e+16</upper>
        </limit>
        <dynamics>
          <damping>1</damping>
          <friction>1</friction>
          <spring_reference>0</spring_reference>
          <spring_stiffness>0</spring_stiffness>
        </dynamics>
      </axis>
    </joint>
    <link name='left_wheel_front'>
      <pose relative_to='left_wheel_hinge_front'>0 0 0 0 -0 0</pose>
      <inertial>
        <pose>0 0 0 0 1.5707 1.5707</pose>
        <mass>5</mass>
        <inertia>
          <ixx>0.1</ixx>
          <ixy>0</ixy>
          <ixz>0</ixz>
          <iyy>0.1</iyy>
          <iyz>0</iyz>
          <izz>0.1</izz>
        </inertia>
      </inertial>
      <collision name='left_wheel_front_collision'>
        <pose>0 0 0 -1.5707 1.5708 0</pose>
        <geometry>
          <cylinder>
            <length>0.0125</length>
            <radius>0.05</radius>
          </cylinder>
        </geometry>
        <surface>
          <contact>
            <ode>
              <kp>1e+06</kp>
              <kd>100</kd>
              <max_vel>1</max_vel>
              <min_depth>0</min_depth>
            </ode>
          </contact>
          <friction>
            <ode>
              <mu>1</mu>
              <mu2>1</mu2>
            </ode>
          </friction>
        </surface>
      </collision>
      <visual name='left_wheel_front_visual'>
        <pose>0 0 0 -1.5707 1.5708 0</pose>
        <geometry>
          <cylinder>
            <length>0.0125</length>
            <radius>0.05</radius>
          </cylinder>
        </geometry>
        <material>
          <script>
            <name>Gazebo/Green</name>
            <uri>file://media/materials/scripts/gazebo.material</uri>
          </script>
        </material>
      </visual>
    </link>
    <joint name='right_wheel_hinge_back' type='revolute'>
      <pose relative_to='robot_footprint'>-0.2 -0.3 0 0 -0 0</pose>
      <parent>robot_footprint</parent>
      <child>right_wheel_back</child>
      <axis>
        <xyz>0 1 0</xyz>
        <limit>
          <effort>10000</effort>
          <velocity>1000</velocity>
          <lower>-1e+16</lower>
          <upper>1e+16</upper>
        </limit>
        <dynamics>
          <damping>1</damping>
          <friction>1</friction>
          <spring_reference>0</spring_reference>
          <spring_stiffness>0</spring_stiffness>
        </dynamics>
      </axis>
    </joint>
    <link name='right_wheel_back'>
      <pose relative_to='right_wheel_hinge_back'>0 0 0 0 -0 0</pose>
      <inertial>
        <pose>0 0 0 0 1.5707 1.5707</pose>
        <mass>5</mass>
        <inertia>
          <ixx>0.1</ixx>
          <ixy>0</ixy>
          <ixz>0</ixz>
          <iyy>0.1</iyy>
          <iyz>0</iyz>
          <izz>0.1</izz>
        </inertia>
      </inertial>
      <collision name='right_wheel_back_collision'>
        <pose>0 0 0 -1.5707 1.5708 0</pose>
        <geometry>
          <cylinder>
            <length>0.05</length>
            <radius>0.1</radius>
          </cylinder>
        </geometry>
        <surface>
          <contact>
            <ode>
              <kp>1e+06</kp>
              <kd>100</kd>
              <max_vel>1</max_vel>
              <min_depth>0</min_depth>
            </ode>
          </contact>
          <friction>
            <ode>
              <mu>1</mu>
              <mu2>1</mu2>
            </ode>
          </friction>
        </surface>
      </collision>
      <visual name='right_wheel_back_visual'>
        <pose>0 0 0 -1.5707 1.5708 0</pose>
        <geometry>
          <cylinder>
            <length>0.05</length>
            <radius>0.1</radius>
          </cylinder>
        </geometry>
        <material>
          <script>
            <name>Gazebo/Green</name>
            <uri>file://media/materials/scripts/gazebo.material</uri>
          </script>
        </material>
      </visual>
    </link>
    <joint name='right_wheel_hinge_front' type='revolute'>
      <pose relative_to='robot_footprint'>0.2 -0.3 -0.1 0 -0 0</pose>
      <parent>robot_footprint</parent>
      <child>right_wheel_front</child>
      <axis>
        <xyz>0 1 0</xyz>
        <limit>
          <effort>10000</effort>
          <velocity>1000</velocity>
          <lower>-1e+16</lower>
          <upper>1e+16</upper>
        </limit>
        <dynamics>
          <damping>1</damping>
          <friction>1</friction>
          <spring_reference>0</spring_reference>
          <spring_stiffness>0</spring_stiffness>
        </dynamics>
      </axis>
    </joint>
    <link name='right_wheel_front'>
      <pose relative_to='right_wheel_hinge_front'>0 0 0 0 -0 0</pose>
      <inertial>
        <pose>0 0 0 0 1.5707 1.5707</pose>
        <mass>5</mass>
        <inertia>
          <ixx>0.1</ixx>
          <ixy>0</ixy>
          <ixz>0</ixz>
          <iyy>0.1</iyy>
          <iyz>0</iyz>
          <izz>0.1</izz>
        </inertia>
      </inertial>
      <collision name='right_wheel_front_collision'>
        <pose>0 0 0 -1.5707 1.5708 0</pose>
        <geometry>
          <cylinder>
            <length>0.0125</length>
            <radius>0.05</radius>
          </cylinder>
        </geometry>
        <surface>
          <contact>
            <ode>
              <kp>1e+06</kp>
              <kd>100</kd>
              <max_vel>1</max_vel>
              <min_depth>0</min_depth>
            </ode>
          </contact>
          <friction>
            <ode>
              <mu>1</mu>
              <mu2>1</mu2>
            </ode>
          </friction>
        </surface>
      </collision>
      <visual name='right_wheel_front_visual'>
        <pose>0 0 0 -1.5707 1.5708 0</pose>
        <geometry>
          <cylinder>
            <length>0.0125</length>
            <radius>0.05</radius>
          </cylinder>
        </geometry>
        <material>
          <script>
            <name>Gazebo/Green</name>
            <uri>file://media/materials/scripts/gazebo.material</uri>
          </script>
        </material>
      </visual>
    </link>
    <static>0</static>
    <plugin name='skid_steer_drive_controller' filename='libgazebo_ros_skid_steer_drive.so'>
      <updateRate>10.0</updateRate>
      <robotNamespace>/carre_sim</robotNamespace>
      <leftFrontJoint>left_wheel_hinge_front</leftFrontJoint>
      <rightFrontJoint>right_wheel_hinge_front</rightFrontJoint>
      <leftRearJoint>left_wheel_hinge_back</leftRearJoint>
      <rightRearJoint>right_wheel_hinge_back</rightRearJoint>
      <wheelSeparation>0.4</wheelSeparation>
      <wheelDiameter>0.2</wheelDiameter>
      <robotBaseFrame>robot_footprint</robotBaseFrame>
      <torque>10</torque>
      <topicName>cmd_vel</topicName>
      <odometryTopic>odom</odometryTopic>
      <odometryFrame>odom</odometryFrame>
      <commandTopic>cmd_vel</commandTopic>
      <topic_name_twist>cmd_vel</topic_name_twist>
      <topic_name_odometry>odom</topic_name_odometry>
      <topic_name_joint>joint</topic_name_joint>
      <broadcastTF>1</broadcastTF>
      <covariance_x>0.0001</covariance_x>
      <covariance_y>0.0001</covariance_y>
      <covariance_yaw>0.01</covariance_yaw>
    </plugin>
  </model>
</sdf>
